Workbook

Sheet MuleIntegrations<=>MuleApps
A1: Sr No | B1: MuleSoft Integrations | C1: MuleSoft Applications | D1: Medium | E1: Comments
A2: 1 | B2: MUL-CONSOLIDATEDINVOICE | C2: columbus-document-papi-v1 | D2: Mixed
A3: 2 | B3: MUL-CONSOLIDATEDINVOICE | C3: columbus-document-sapi-v1 | D3: Mixed
A4: 3 | B4: MUL-CONSOLIDATEDINVOICE | C4: customer-document-papi-v1 | D4: Mixed
A5: 4 | B5: MUL-CONSOLIDATEDINVOICE | C5: hx-sftp-sapi-v1 | D5: Mixed
A6: 5 | B6: MUL-CONSOLIDATEDINVOICE | C6: invoice-papi-v1 | D6: Mixed
A7: 6 | B7: MUL-CONSOLIDATEDINVOICE | C7: sfdc-order-sapi-v1 | D7: Mixed
A8: 7 | B8: MUL-CONSOLIDATEDINVOICE | C8: sfdc-product-sapi-v1 | D8: Mixed
A9: 8 | B9: MUL-CONSOLIDATEDINVOICE | C9: vanstock-invoice-sapi-v1 | D9: Mixed
A10: 9 | B10: MUL-DIGITALASSET | C10: azure-blob-storage-sapi-v1 | D10: API
A11: 10 | B11: MUL-DIGITALASSET | C11: digitalasset-papi-v1 | D11: API
A12: 11 | B12: MUL-DIGITALASSET | C12: cloudinary-digitalasset-sapi-live | D12: API
A13: 12 | B13: MUL-COLUMBUS-DOC-HYBRIS | C13: api-hybrisdocuments-v2 | D13: API
... A16: 15 | B16: MUL-COLUMBUS-DOC-HYBRIS | C16: mule-oauth-provider | D16: API
A17: 16 | B17: MUL-COLUMBUSFILES | C17: columbus-document-papi-v1 | D17: File Transfer | E17: FelixToAzureStarkAndColumbus UAT Pending
A18: 17 | B18: MUL-COLUMBUSFILES | C18: columbus-document-sapi-v1 | D18: File Transfer | E18: HxToAzureStarkAndColumbus UAT pending
A19: 18 | B19: MUL-COLUMBUSFILES | C19: icon-sftp-sapi-v1 | D19: File Transfer
A20: 19 | B20: MUL-COLUMBUSFILES | C20: felix-sftp-sapi-v1 | D20: File Transfer | E20: FelixToAzureStarkAndColumbus UAT Pending
A21: 20 | B21: MUL-COLUMBUSFILES | C21: hx-sftp-sapi-v1 | D21: File Transfer | E21: HxToAzureStarkAndColumbus UAT pending
A22: 21 | B22: MUL-COLUMBUS-DOCUMENTS | C22: document-eapi-v2 | D22: API
A23: 22 | B23: MUL-COLUMBUS-DOCUMENTS | C23: document-papi-v1 | D23: API
A24: 23 | B24: MUL-COLUMBUS-DOCUMENTS | C24: columbus-document-sapi-v1 | D24: API
A25: 24 | B25: MUL-COLUMBUS-DOCUMENTS | C25: mule-oauth-provider | D25: API
A26: 25 | B26: MUL-ACCOUNT-VALIDATION | C26: account-validation-eapi-v1 | D26: Mixed
A27: 26 | B27: MUL-ACCOUNT-VALIDATION | C27: account-validation-papi-v1 | D27: Mixed
A28: 27 | B28: MUL-ACCOUNT-VALIDATION | C28: icon-account-sapi-v1 | D28: Mixed
A29: 28 | B29: MUL-ACCOUNT-VALIDATION | C29: dbm-sapi-v1 | D29: Mixed
A30: 29 | B30: MUL-ACCOUNT-VALIDATION | C30: pmsolutions-sapi-v1 | D30: Mixed
A31: 30 | B31: MUL-ACCOUNT-VALIDATION | C31: mule-oauth-provider | D31: Mixed
A32: 31 | B32: MUL-TIMBERDATABASE | C32: timber-papi-v1 | D32: File Transfer | E32: UAT pending
A33: 32 | B33: MUL-TIMBERDATABASE | C33: felix-sftp-sapi-v1 | D33: File Transfer | E33: UAT pending
A34: 33 | B34: MUL-TIMBERDATABASE | C34: azure-file-sapi-v1 | D34: File Transfer | E34: UAT pending
A35: 34 | B35: MUL-FLEETWAVE-ICON-COGNITO | C35: transport-papi-v1 | D35: Mixed | E35: UAT pending
A36: 35 | B36: MUL-FLEETWAVE-ICON-COGNITO | C36: fleetwave-sapi-v1 | D36: Mixed | E36: UAT pending
A37: 36 | B37: MUL-FLEETWAVE-ICON-COGNITO | C37: icon-sftp-sapi-v1 | D37: Mixed | E37: UAT pending
A38: 37 | B38: MUL-FLEETWAVE-ICON-COGNITO | C38: cognito-sapi-v1 | D38: Mixed | E38: UAT pending
A39: 38 | B39: MUL-TRIPDATA | C39: rac-sapi-v1 | D39: API | E39: Out of Scope
A40: 39 | B40: MUL-TRIPDATA | C40: fleetwave-sapi-v1 | D40: API | E40: Out of Scope
A41: 40 | B41: MUL-SWIFT6-TRANSPORT | C41: transport-papi-v1 | D41: Mixed | E41: Out of Scope
A42: 41 | B42: MUL-SWIFT6-TRANSPORT | C42: fleetwave-sapi-v1 | D42: Mixed | E42: Out of Scope
...

Sheet MuleApps<=>MuleIntegrations
A1: Sr No | B1: MuleSoft Applications | C1: MuleSoft Integrations | D1: Medium | E1: Comments
A2: 1 | B2: columbus-document-papi-v1 | C2: MUL-CONSOLIDATEDINVOICE | D2: Mixed
A3: 2 | B3: columbus-document-sapi-v1 | C3: MUL-CONSOLIDATEDINVOICE | D3: Mixed
A4: 3 | B4: customer-document-papi-v1 | C4: MUL-CONSOLIDATEDINVOICE | D4: Mixed
A5: 4 | B5: hx-sftp-sapi-v1 | C5: MUL-CONSOLIDATEDINVOICE | D5: Mixed
A6: 5 | B6: invoice-papi-v1 | C6: MUL-CONSOLIDATEDINVOICE | D6: Mixed
A7: 6 | B7: sfdc-order-sapi-v1 | C7: MUL-CONSOLIDATEDINVOICE | D7: Mixed
A8: 7 | B8: sfdc-product-sapi-v1 | C8: MUL-CONSOLIDATEDINVOICE | D8: Mixed
A9: 8 | B9: vanstock-invoice-sapi-v1 | C9: MUL-CONSOLIDATEDINVOICE | D9: Mixed
A10: 9 | B10: azure-blob-storage-sapi-v1 | C10: MUL-DIGITALASSET | D10: API
A11: 10 | B11: digitalasset-papi-v1 | C11: MUL-DIGITALASSET | D11: API
A12: 11 | B12: cloudinary-digitalasset-sapi-live | C12: MUL-DIGITALASSET | D12: API
A13: 12 | B13: api-hybrisdocuments-v2 | C13: MUL-COLUMBUS-DOC-HYBRIS | D13: API
... A16: 15 | B16: mule-oauth-provider | C16: MUL-COLUMBUS-DOC-HYBRIS | D16: API
A17: 16 | B17: columbus-document-papi-v1 | C17: MUL-COLUMBUSFILES | D17: File Transfer | E17: FelixToAzureStarkAndColumbus UAT Pending
A18: 17 | B18: columbus-document-sapi-v1 | C18: MUL-COLUMBUSFILES | D18: File Transfer | E18: HxToAzureStarkAndColumbus UAT pending
A19: 18 | B19: icon-sftp-sapi-v1 | C19: MUL-COLUMBUSFILES | D19: File Transfer
A20: 19 | B20: felix-sftp-sapi-v1 | C20: MUL-COLUMBUSFILES | D20: File Transfer | E20: FelixToAzureStarkAndColumbus UAT Pending
A21: 20 | B21: hx-sftp-sapi-v1 | C21: MUL-COLUMBUSFILES | D21: File Transfer | E21: HxToAzureStarkAndColumbus UAT pending
A22: 21 | B22: document-eapi-v2 | C22: MUL-COLUMBUS-DOCUMENTS | D22: API
A23: 22 | B23: document-papi-v1 | C23: MUL-COLUMBUS-DOCUMENTS | D23: API
A24: 23 | B24: columbus-document-sapi-v1 | C24: MUL-COLUMBUS-DOCUMENTS | D24: API
A25: 24 | B25: mule-oauth-provider | C25: MUL-COLUMBUS-DOCUMENTS | D25: API
A26: 25 | B26: account-validation-eapi-v1 | C26: MUL-ACCOUNT-VALIDATION | D26: Mixed
A27: 26 | B27: account-validation-papi-v1 | C27: MUL-ACCOUNT-VALIDATION | D27: Mixed
A28: 27 | B28: icon-account-sapi-v1 | C28: MUL-ACCOUNT-VALIDATION | D28: Mixed
A29: 28 | B29: dbm-sapi-v1 | C29: MUL-ACCOUNT-VALIDATION | D29: Mixed
A30: 29 | B30: pmsolutions-sapi-v1 | C30: MUL-ACCOUNT-VALIDATION | D30: Mixed
A31: 30 | B31: mule-oauth-provider | C31: MUL-ACCOUNT-VALIDATION | D31: Mixed
A32: 31 | B32: timber-papi-v1 | C32: MUL-TIMBERDATABASE | D32: File Transfer | E32: UAT pending
A33: 32 | B33: felix-sftp-sapi-v1 | C33: MUL-TIMBERDATABASE | D33: File Transfer | E33: UAT pending
A34: 33 | B34: azure-file-sapi-v1 | C34: MUL-TIMBERDATABASE | D34: File Transfer | E34: UAT pending
A35: 34 | B35: transport-papi-v1 | C35: MUL-FLEETWAVE-ICON-COGNITO | D35: Mixed | E35: UAT pending
A36: 35 | B36: fleetwave-sapi-v1 | C36: MUL-FLEETWAVE-ICON-COGNITO | D36: Mixed | E36: UAT pending
A37: 36 | B37: icon-sftp-sapi-v1 | C37: MUL-FLEETWAVE-ICON-COGNITO | D37: Mixed | E37: UAT pending
A38: 37 | B38: cognito-sapi-v1 | C38: MUL-FLEETWAVE-ICON-COGNITO | D38: Mixed | E38: UAT pending
A39: 38 | B39: rac-sapi-v1 | C39: MUL-TRIPDATA | D39: API | E39: Out of Scope
A40: 39 | B40: fleetwave-sapi-v1 | C40: MUL-TRIPDATA | D40: API | E40: Out of Scope
A41: 40 | B41: transport-papi-v1 | C41: MUL-SWIFT6-TRANSPORT | D41: Mixed | E41: Out of Scope
A42: 41 | B42: fleetwave-sapi-v1 | C42: MUL-SWIFT6-TRANSPORT | D42: Mixed | E42: Out of Scope
...

Sheet All-Prod-MuleApps
A1: Sr No | B1: MuleSoft Applications | C1: Prod Status | D1: Comments | E1: Normalised name | F1: Integration | G1: Medium
A2: 1 | B2: starkuk-live-sfdc-accounts-sapi-v1 | C2: Started | E2: sfdc-accounts-sapi-v1 | F2: =VLOOKUP(E2,'MuleApps<=>MuleIntegrations'!B:C,2,FALSE) -> MUL-CONSENT | G2: =VLOOKUP(E2,'MuleApps<=>MuleIntegrations'!B:D,3,FALSE) -> Mixed
A3: 2 | B3: starkuk-live-wesupply-sftp-sapi-v1 | C3: Started | E3: wesupply-sftp-sapi-v1 | F3: =VLOOKUP(E3,'MuleApps<=>MuleIntegrations'!B:C,2,FALSE) -> MUL-SUPPLIER-PO | G3: =VLOOKUP(E3,'MuleApps<=>MuleIntegrations'!B:D,3,FALSE) -> File Transfer
A4: 3 | B4: sgbd-live-azure-blob-storage-sapi-v1 | C4: Started | E4: azure-blob-storage-sapi-v1 | F4: =VLOOKUP(E4,'MuleApps<=>MuleIntegrations'!B:C,2,FALSE) -> MUL-DIGITALASSET | G4: =VLOOKUP(E4,'MuleApps<=>MuleIntegrations'!B:D,3,FALSE) -> API
A5: 4 | B5: starkuk-live-icov-customersftp-sapi-v1 | C5: Started | E5: icov-customersftp-sapi-v1 | F5: =VLOOKUP(E5,'MuleApps<=>MuleIntegrations'!B:C,2,FALSE) -> MUL-CUSTORDERVALIDATION | G5: =VLOOKUP(E5,'MuleApps<=>MuleIntegrations'!B:D,3,FALSE) -> Mixed
A6: 5 | B6: starkuk-live-ovm-services-eapi-v1 | C6: Started | E6: ovm-services-eapi-v1 | F6: =VLOOKUP(E6,'MuleApps<=>MuleIntegrations'!B:C,2,FALSE) -> MUL-OPCARDS | G6: =VLOOKUP(E6,'MuleApps<=>MuleIntegrations'!B:D,3,FALSE) -> API
A7: 6 | B7: starkuk-live-bi-papi-v1 | C7: Undeployed | E7: bi-papi-v1 | F7: =VLOOKUP(E7,'MuleApps<=>MuleIntegrations'!B:C,2,FALSE) -> MUL-DATALAKE | G7: =VLOOKUP(E7,'MuleApps<=>MuleIntegrations'!B:D,3,FALSE) -> File Transfer
A8: 7 | B8: starkuk-live-icon-contact-eapi-v1 | C8: Started | E8: icon-contact-eapi-v1 | F8: =VLOOKUP(E8,'MuleApps<=>MuleIntegrations'!B:C,2,FALSE) -> MUL-CONSENT | G8: =VLOOKUP(E8,'MuleApps<=>MuleIntegrations'!B:D,3,FALSE) -> Mixed
A9: 8 | B9: starkuk-live-icon-contact-sapi-v1 | C9: Started | E9: icon-contact-sapi-v1 | F9: =VLOOKUP(E9,'MuleApps<=>MuleIntegrations'!B:C,2,FALSE) -> MUL-CONSENT | G9: =VLOOKUP(E9,'MuleApps<=>MuleIntegrations'!B:D,3,FALSE) -> Mixed
A10: 9 | B10: starkuk-live-po-proposal-papi-v1 | C10: Started | E10: po-proposal-papi-v1 | F10: =VLOOKUP(E10,'MuleApps<=>MuleIntegrations'!B:C,2,FALSE) -> MUL-INVENTORYAUTOMATION | G10: =VLOOKUP(E10,'MuleApps<=>MuleIntegrations'!B:D,3,FALSE) -> Mixed
A11: 10 | B11: starkuk-live-icon-account-sapi-v1 | C11: Started | E11: icon-account-sapi-v1 | F11: =VLOOKUP(E11,'MuleApps<=>MuleIntegrations'!B:C,2,FALSE) -> MUL-ACCOUNT-VALIDATION | G11: =VLOOKUP(E11,'MuleApps<=>MuleIntegrations'!B:D,3,FALSE) -> Mixed
A12: 11 | B12: starkuk-live-icon-product-sapi-v1 | C12: Started | E12: icon-product-sapi-v1 | F12: =VLOOKUP(E12,'MuleApps<=>MuleIntegrations'!B:C,2,FALSE) -> MUL-PUNCHOUT | G12: =VLOOKUP(E12,'MuleApps<=>MuleIntegrations'!B:D,3,FALSE) -> API
A13: 12 | B13: starkuk-live-product-sapi-v2 | C13: Started | E13: product-sapi-v2 | F13: =VLOOKUP(E13,'MuleApps<=>MuleIntegrations'!B:C,2,FALSE) -> MUL-PRODUCTS | G13: =VLOOKUP(E13,'MuleApps<=>MuleIntegrations'!B:D,3,FALSE) -> API
... A112: 111 | B112: starkuk-prod-cognito-sapi-v1 | C112: Started | E112: cognito-sapi-v1 | F112: =VLOOKUP(E112,'MuleApps<=>MuleIntegrations'!B:C,2,FALSE) -> MUL-FLEETWAVE-ICON-COGNITO | G112: =VLOOKUP(E112,'MuleApps<=>MuleIntegrations'!B:D,3,FALSE) -> Mixed

Sheet All-Prod-Mule-Triggers
A1: Sr No | B1: MuleSoft Applications | C1: TriggerName | D1: Scheduletime | E1: Prod Status | F1: Comments | G1: Normalised name | H1: Integration | I1: Medium
A2: 1 | B2: starkuk-live-pmsolutions-papi-v1 | C2: icon-to-pmsolutions-papi-flow_Scheduler | D2: 0 0 9,10 ? * * | E2: Enabled | G2: pmsolutions-papi-v1 | H2: =VLOOKUP(G2,'MuleApps<=>MuleIntegrations'!B:C,2,FALSE) -> MUL-MINSTER-NEW-ACCS | I2: =VLOOKUP(G2,'MuleApps<=>MuleIntegrations'!B:D,3,FALSE) -> File Transfer
A3: 2 | B3: starkuk-live-pmsolutions-papi-v1 | C3: outbound-reprocessing-scheduler-flow_Scheduler | D3: 0 30 9 ? * * | E3: Enabled | G3: pmsolutions-papi-v1 | H3: =VLOOKUP(G3,'MuleApps<=>MuleIntegrations'!B:C,2,FALSE) -> MUL-MINSTER-NEW-ACCS | I3: =VLOOKUP(G3,'MuleApps<=>MuleIntegrations'!B:D,3,FALSE) -> File Transfer
A4: 3 | B4: starkuk-live-bi-papi-v1 | C4: clear-token-scheduler_Scheduler | D4: 0 0 2 * * ? * | E4: Enabled | G4: bi-papi-v1 | H4: =VLOOKUP(G4,'MuleApps<=>MuleIntegrations'!B:C,2,FALSE) -> MUL-DATALAKE | I4: =VLOOKUP(G4,'MuleApps<=>MuleIntegrations'!B:D,3,FALSE) -> File Transfer
A5: 4 | B5: starkuk-live-bi-papi-v1 | C5: hx-org-grn-scheduler_org and grn files | E5: Disabled | G5: bi-papi-v1 | H5: =VLOOKUP(G5,'MuleApps<=>MuleIntegrations'!B:C,2,FALSE) -> MUL-DATALAKE | I5: =VLOOKUP(G5,'MuleApps<=>MuleIntegrations'!B:D,3,FALSE) -> File Transfer
A6: 5 | B6: starkuk-live-bi-papi-v1 | C6: hx-term-scheduler_Term files | E6: Disabled | G6: bi-papi-v1 | H6: =VLOOKUP(G6,'MuleApps<=>MuleIntegrations'!B:C,2,FALSE) -> MUL-DATALAKE | I6: =VLOOKUP(G6,'MuleApps<=>MuleIntegrations'!B:D,3,FALSE) -> File Transfer
A7: 6 | B7: starkuk-live-bi-papi-v1 | C7: icon-BC_ICRP-scheduler_Scheduler | E7: Disabled | G7: bi-papi-v1 | H7: =VLOOKUP(G7,'MuleApps<=>MuleIntegrations'!B:C,2,FALSE) -> MUL-DATALAKE | I7: =VLOOKUP(G7,'MuleApps<=>MuleIntegrations'!B:D,3,FALSE) -> File Transfer
A8: 7 | B8: starkuk-live-bi-papi-v1 | C8: icon-mans-scheduler_Scheduler | E8: Disabled | G8: bi-papi-v1 | H8: =VLOOKUP(G8,'MuleApps<=>MuleIntegrations'!B:C,2,FALSE) -> MUL-DATALAKE | I8: =VLOOKUP(G8,'MuleApps<=>MuleIntegrations'!B:D,3,FALSE) -> File Transfer
A9: 8 | B9: starkuk-live-bi-papi-v1 | C9: icon-scheduler-for-product-additional-files_Scheduler | E9: Disabled | G9: bi-papi-v1 | H9: =VLOOKUP(G9,'MuleApps<=>MuleIntegrations'!B:C,2,FALSE) -> MUL-DATALAKE | I9: =VLOOKUP(G9,'MuleApps<=>MuleIntegrations'!B:D,3,FALSE) -> File Transfer
A10: 9 | B10: starkuk-live-bi-papi-v1 | C10: icon-scheduler-for-supplier-additional-files_Scheduler | E10: Disabled | G10: bi-papi-v1 | H10: =VLOOKUP(G10,'MuleApps<=>MuleIntegrations'!B:C,2,FALSE) -> MUL-DATALAKE | I10: =VLOOKUP(G10,'MuleApps<=>MuleIntegrations'!B:D,3,FALSE) -> File Transfer
A11: 10 | B11: starkuk-live-bi-papi-v1 | C11: icon-scheduler_Scheduler | E11: Disabled | G11: bi-papi-v1 | H11: =VLOOKUP(G11,'MuleApps<=>MuleIntegrations'!B:C,2,FALSE) -> MUL-DATALAKE | I11: =VLOOKUP(G11,'MuleApps<=>MuleIntegrations'!B:D,3,FALSE) -> File Transfer
A12: 11 | B12: starkuk-live-bi-papi-v1 | C12: phocas-scheduler_Scheduler | E12: Disabled | G12: bi-papi-v1 | H12: =VLOOKUP(G12,'MuleApps<=>MuleIntegrations'!B:C,2,FALSE) -> MUL-DATALAKE | I12: =VLOOKUP(G12,'MuleApps<=>MuleIntegrations'!B:D,3,FALSE) -> File Transfer
A13: 12 | B13: starkuk-live-bi-papi-v1 | C13: send-token-scheduler_Scheduler | D13: 0 0/30 0-1,6,17-23 * * ? | E13: Enabled | G13: bi-papi-v1 | H13: =VLOOKUP(G13,'MuleApps<=>MuleIntegrations'!B:C,2,FALSE) -> MUL-DATALAKE | I13: =VLOOKUP(G13,'MuleApps<=>MuleIntegrations'!B:D,3,FALSE) -> File Transfer
A14: 13 | B14: starkuk-live-timber-papi-v1 | C14: felix-to-azure-scheduler-flow_felix-to-azure-scheduler | E14: Disabled | G14: timber-papi-v1 | H14: =VLOOKUP(G14,'MuleApps<=>MuleIntegrations'!B:C,2,FALSE) -> MUL-TIMBERDATABASE | I14: =VLOOKUP(G14,'MuleApps<=>MuleIntegrations'!B:D,3,FALSE) -> File Transfer
A15: 14 | B15: starkuk-live-timber-papi-v1 | C15: icon-to-felix-scheduler-flow_icon-felix-scheduler | E15: Disabled | G15: timber-papi-v1 | H15: =VLOOKUP(G15,'MuleApps<=>MuleIntegrations'!B:C,2,FALSE) -> MUL-TIMBERDATABASE | I15: =VLOOKUP(G15,'MuleApps<=>MuleIntegrations'!B:D,3,FALSE) -> File Transfer
A16: 15 | B16: starkuk-live-timber-papi-v1 | C16: timber-to-felix-scheduler-flow_timber-felix-scheduler | E16: Disabled | G16: timber-papi-v1 | H16: =VLOOKUP(G16,'MuleApps<=>MuleIntegrations'!B:C,2,FALSE) -> MUL-TIMBERDATABASE | I16: =VLOOKUP(G16,'MuleApps<=>MuleIntegrations'!B:D,3,FALSE) -> File Transfer
A17: 16 | B17: starkuk-live-ovm-papi-v1 | C17: ovm-papi-main-scheduler-flow_Scheduler | D17: 0 0/30 6-19 ? * MON,TUE,WED,THU,FRI,SAT * | E17: Enabled | G17: ovm-papi-v1 | H17: =VLOOKUP(G17,'MuleApps<=>MuleIntegrations'!B:C,2,FALSE) -> MUL-CUSTORDERVALIDATION | I17: =VLOOKUP(G17,'MuleApps<=>MuleIntegrations'!B:D,3,FALSE) -> Mixed
A18: 17 | B18: starkuk-live-ovm-papi-v1 | C18: ovm-papi-reprocessing-scheduler-flow_Scheduler | D18: 0 0/15 * ? * * * | E18: Enabled | G18: ovm-papi-v1 | H18: =VLOOKUP(G18,'MuleApps<=>MuleIntegrations'!B:C,2,FALSE) -> MUL-CUSTORDERVALIDATION | I18: =VLOOKUP(G18,'MuleApps<=>MuleIntegrations'!B:D,3,FALSE) -> Mixed
A19: 18 | B19: starkuk-live-ovm-papi-v1 | C19: ovm-papi-start-of-the-day-scheduler-flow_Scheduler | D19: 0 0 8 ? * * * | E19: Enabled | G19: ovm-papi-v1 | H19: =VLOOKUP(G19,'MuleApps<=>MuleIntegrations'!B:C,2,FALSE) -> MUL-CUSTORDERVALIDATION | I19: =VLOOKUP(G19,'MuleApps<=>MuleIntegrations'!B:D,3,FALSE) -> Mixed
A20: 19 | B20: starkuk-live-bi-papi-v2 | C20: felix-to-salesi-via-outbound-proxy-sapi_felix-to-salesi | E20: Disabled | G20: bi-papi-v2 | H20: =VLOOKUP(G20,'MuleApps<=>MuleIntegrations'!B:C,2,FALSE) -> MUL-ERP-3rd-PARTY | I20: =VLOOKUP(G20,'MuleApps<=>MuleIntegrations'!B:D,3,FALSE) -> File Transfer
A21: 20 | B21: starkuk-live-bi-papi-v2 | C21: hx-dumps-to-internal-flow_hx-dumps-to-internal | E21: Disabled | G21: bi-papi-v2 | H21: =VLOOKUP(G21,'MuleApps<=>MuleIntegrations'!B:C,2,FALSE) -> MUL-ERP-3rd-PARTY | I21: =VLOOKUP(G21,'MuleApps<=>MuleIntegrations'!B:D,3,FALSE) -> File Transfer
A22: 21 | B22: starkuk-live-bi-papi-v2 | C22: hx-informatica-to-internal-sftp-flow_scheduler | E22: Disabled | G22: bi-papi-v2 | H22: =VLOOKUP(G22,'MuleApps<=>MuleIntegrations'!B:C,2,FALSE) -> MUL-ERP-3rd-PARTY | I22: =VLOOKUP(G22,'MuleApps<=>MuleIntegrations'!B:D,3,FALSE) -> File Transfer
A23: 22 | B23: starkuk-live-bi-papi-v2 | C23: hx-to-concur-flow_hx-concur-scheduler | D23: 0 0 18 * * ? * | E23: Enabled | G23: bi-papi-v2 | H23: =VLOOKUP(G23,'MuleApps<=>MuleIntegrations'!B:C,2,FALSE) -> MUL-ERP-3rd-PARTY | I23: =VLOOKUP(G23,'MuleApps<=>MuleIntegrations'!B:D,3,FALSE) -> File Transfer
A24: 23 | B24: starkuk-live-bi-papi-v2 | C24: hx-to-dbm-flow_hx-to-dbm-scheduler | E24: Disabled | G24: bi-papi-v2 | H24: =VLOOKUP(G24,'MuleApps<=>MuleIntegrations'!B:C,2,FALSE) -> MUL-ERP-3rd-PARTY | I24: =VLOOKUP(G24,'MuleApps<=>MuleIntegrations'!B:D,3,FALSE) -> File Transfer
A25: 24 | B25: starkuk-live-bi-papi-v2 | C25: hx-to-internal-sftp-sapi-flow_hx-to-internal | E25: Disabled | G25: bi-papi-v2 | H25: =VLOOKUP(G25,'MuleApps<=>MuleIntegrations'!B:C,2,FALSE) -> MUL-ERP-3rd-PARTY | I25: =VLOOKUP(G25,'MuleApps<=>MuleIntegrations'!B:D,3,FALSE) -> File Transfer
A26: 25 | B26: starkuk-live-bi-papi-v2 | C26: hx-to-proactis-via-outbound-proxy-sapi-flow_Scheduler | E26: Disabled | G26: bi-papi-v2 | H26: =VLOOKUP(G26,'MuleApps<=>MuleIntegrations'!B:C,2,FALSE) -> MUL-ERP-3rd-PARTY | I26: =VLOOKUP(G26,'MuleApps<=>MuleIntegrations'!B:D,3,FALSE) -> File Transfer
A27: 26 | B27: starkuk-live-bi-papi-v2 | C27: icon-account-handler-cash-flow_Scheduler | E27: Disabled | G27: bi-papi-v2 | H27: =VLOOKUP(G27,'MuleApps<=>MuleIntegrations'!B:C,2,FALSE) -> MUL-ERP-3rd-PARTY | I27: =VLOOKUP(G27,'MuleApps<=>MuleIntegrations'!B:D,3,FALSE) -> File Transfer
A28: 27 | B28: starkuk-live-bi-papi-v2 | C28: icon-account-handler-credit-flow_Scheduler | E28: Disabled | G28: bi-papi-v2 | H28: =VLOOKUP(G28,'MuleApps<=>MuleIntegrations'!B:C,2,FALSE) -> MUL-ERP-3rd-PARTY | I28: =VLOOKUP(G28,'MuleApps<=>MuleIntegrations'!B:D,3,FALSE) -> File Transfer
A29: 28 | B29: starkuk-live-bi-papi-v2 | C29: icon-account-handler-marketing-flow_Scheduler | E29: Disabled | G29: bi-papi-v2 | H29: =VLOOKUP(G29,'MuleApps<=>MuleIntegrations'!B:C,2,FALSE) -> MUL-ERP-3rd-PARTY | I29: =VLOOKUP(G29,'MuleApps<=>MuleIntegrations'!B:D,3,FALSE) -> File Transfer
A30: 29 | B30: starkuk-live-bi-papi-v2 | C30: icon-account-handler-reject-flow_Scheduler | E30: Disabled | G30: bi-papi-v2 | H30: =VLOOKUP(G30,'MuleApps<=>MuleIntegrations'!B:C,2,FALSE) -> MUL-ERP-3rd-PARTY | I30: =VLOOKUP(G30,'MuleApps<=>MuleIntegrations'!B:D,3,FALSE) -> File Transfer
A31: 30 | B31: starkuk-live-bi-papi-v2 | C31: icon-ecs-to-blob-flow_icon-ecs-to-stark-azure-blob | E31: Disabled | G31: bi-papi-v2 | H31: =VLOOKUP(G31,'MuleApps<=>MuleIntegrations'!B:C,2,FALSE) -> MUL-ERP-3rd-PARTY | I31: =VLOOKUP(G31,'MuleApps<=>MuleIntegrations'!B:D,3,FALSE) -> File Transfer
A32: 31 | B32: starkuk-live-bi-papi-v2 | C32: icon-sql-to-internal-scheduler-flow_icon-sql-to-internal-scheduler | E32: Disabled | G32: bi-papi-v2 | H32: =VLOOKUP(G32,'MuleApps<=>MuleIntegrations'!B:C,2,FALSE) -> MUL-ERP-3rd-PARTY | I32: =VLOOKUP(G32,'MuleApps<=>MuleIntegrations'!B:D,3,FALSE) -> File Transfer
A33: 32 | B33: starkuk-live-bi-papi-v2 | C33: icon-to-insight-flow_Scheduler | E33: Disabled | G33: bi-papi-v2 | H33: =VLOOKUP(G33,'MuleApps<=>MuleIntegrations'!B:C,2,FALSE) -> MUL-ERP-3rd-PARTY | I33: =VLOOKUP(G33,'MuleApps<=>MuleIntegrations'!B:D,3,FALSE) -> File Transfer
A34: 33 | B34: starkuk-live-bi-papi-v2 | C34: internal-to-icertis-flow_internal-to-icertis | E34: Disabled | G34: bi-papi-v2 | H34: =VLOOKUP(G34,'MuleApps<=>MuleIntegrations'!B:C,2,FALSE) -> MUL-ERP-3rd-PARTY | I34: =VLOOKUP(G34,'MuleApps<=>MuleIntegrations'!B:D,3,FALSE) -> File Transfer
A35: 34 | B35: starkuk-live-bi-papi-v2 | C35: internal-to-insight-flow_internal-to-insight-scheduler | E35: Disabled | G35: bi-papi-v2 | H35: =VLOOKUP(G35,'MuleApps<=>MuleIntegrations'!B:C,2,FALSE) -> MUL-ERP-3rd-PARTY | I35: =VLOOKUP(G35,'MuleApps<=>MuleIntegrations'!B:D,3,FALSE) -> File Transfer
A36: 35 | B36: starkuk-live-bi-papi-v2 | C36: stark-azure-to-insight-flow_stark-azure-to-insight-scheduler | E36: Disabled | G36: bi-papi-v2 | H36: =VLOOKUP(G36,'MuleApps<=>MuleIntegrations'!B:C,2,FALSE) -> MUL-ERP-3rd-PARTY | I36: =VLOOKUP(G36,'MuleApps<=>MuleIntegrations'!B:D,3,FALSE) -> File Transfer
A37: 36 | B37: starkuk-live-columbus-document-papi-v1 | C37: cognizant-sftp-to-columbus-blob-schedule_cognizant-to-columbus | D37: 0 1 0 ? * * * | E37: Enabled | G37: columbus-document-papi-v1 | H37: =VLOOKUP(G37,'MuleApps<=>MuleIntegrations'!B:C,2,FALSE) -> MUL-CONSOLIDATEDINVOICE | I37: =VLOOKUP(G37,'MuleApps<=>MuleIntegrations'!B:D,3,FALSE) -> Mixed
A38: 37 | B38: starkuk-live-columbus-document-papi-v1 | C38: felix-to-columbus-flow_felix-to-columbus-scheduler | E38: Disabled | G38: columbus-document-papi-v1 | H38: =VLOOKUP(G38,'MuleApps<=>MuleIntegrations'!B:C,2,FALSE) -> MUL-CONSOLIDATEDINVOICE | I38: =VLOOKUP(G38,'MuleApps<=>MuleIntegrations'!B:D,3,FALSE) -> Mixed
A39: 38 | B39: starkuk-live-columbus-document-papi-v1 | C39: felix-to-stark-azure-and-columbus-flow_Scheduler | E39: Disabled | G39: columbus-document-papi-v1 | H39: =VLOOKUP(G39,'MuleApps<=>MuleIntegrations'!B:C,2,FALSE) -> MUL-CONSOLIDATEDINVOICE | I39: =VLOOKUP(G39,'MuleApps<=>MuleIntegrations'!B:D,3,FALSE) -> Mixed
A40: 39 | B40: starkuk-live-columbus-document-papi-v1 | C40: hx-to-columbus-flow_hx-to-columbus-scheduler | E40: Disabled | G40: columbus-document-papi-v1 | H40: =VLOOKUP(G40,'MuleApps<=>MuleIntegrations'!B:C,2,FALSE) -> MUL-CONSOLIDATEDINVOICE | I40: =VLOOKUP(G40,'MuleApps<=>MuleIntegrations'!B:D,3,FALSE) -> Mixed
...
